<?xml version="1.0" ?>
<!-- =================================================================================== -->
<!-- |    This document was autogenerated by xacro from warthog.urdf.xacro             | -->
<!-- |    EDITING THIS FILE BY HAND IS NOT RECOMMENDED                                 | -->
<!-- =================================================================================== -->
<robot name="warthog" xmlns:xacro="http://www.ros.org/wiki/xacro">
  <material name="dark_grey">
    <color rgba="0.2 0.2 0.2 1.0"/>
  </material>
  <material name="light_grey">
    <color rgba="0.4 0.4 0.4 1.0"/>
  </material>
  <material name="yellow">
    <color rgba="0.95 0.816 0.082 1.0"/>
  </material>
  <material name="black">
    <color rgba="0.15 0.15 0.15 1.0"/>
  </material>
  <material name="white">
    <color rgba="0.9 0.9 0.9 1.0"/>
  </material>
  <material name="red">
    <color rgba="0.9 0.0 0.0 1.0"/>
  </material>
  <link name="front_left_wheel_link">
    <inertial>
      <origin rpy="0 0 0" xyz="0 0 0"/>
      <mass value="15"/>
      <inertia ixx="0.415625" ixy="0" ixz="0" iyy="0.675" iyz="0" izz="0.415625"/>
    </inertial>
    <visual>
      <origin rpy="0 0 1.57079632679" xyz="0 0 0"/>
      <geometry>
        <mesh filename="package://platform_description/meshes/wheel.stl"/>
      </geometry>
      <material name="dark_grey"/>
    </visual>
    <collision>
      <origin rpy="1.57079632679 0 0" xyz="0 0 0"/>
      <geometry>
        <cylinder length="0.25" radius="0.3"/>
      </geometry>
    </collision>
  </link>
  <joint name="front_left_wheel_joint" type="continuous">
    <parent link="left_diff_unit_link"/>
    <child link="front_left_wheel_link"/>
    <origin rpy="0 0 0" xyz="0.457367 0.0 -0.012977"/>
    <axis xyz="0 1 0"/>
  </joint>
  <gazebo reference="front_left_wheel_link">
    <selfCollide>false</selfCollide>
    <mu1>0.5</mu1>
    <mu2>0.5</mu2>
    <kp value="10000000.0"/>
    <kd value="1.0"/>
    <fdir1 value="1 0 0"/>
    <material>Gazebo/Grey</material>
  </gazebo>
  <transmission name="front_left_wheel_trans">
    <type>transmission_interface/SimpleTransmission</type>
    <joint name="front_left_wheel_joint">
      <hardwareInterface>hardware_interface/VelocityJointInterface</hardwareInterface>
    </joint>
    <actuator name="front_left_actuator">
      <hardwareInterface>hardware_interface/VelocityJointInterface</hardwareInterface>
      <mechanicalReduction>1</mechanicalReduction>
    </actuator>
  </transmission>
  <link name="front_right_wheel_link">
    <inertial>
      <origin rpy="0 0 0" xyz="0 0 0"/>
      <mass value="15"/>
      <inertia ixx="0.415625" ixy="0" ixz="0" iyy="0.675" iyz="0" izz="0.415625"/>
    </inertial>
    <visual>
      <origin rpy="0 0 1.57079632679" xyz="0 0 0"/>
      <geometry>
        <mesh filename="package://platform_description/meshes/wheel.stl"/>
      </geometry>
      <material name="dark_grey"/>
    </visual>
    <collision>
      <origin rpy="1.57079632679 0 0" xyz="0 0 0"/>
      <geometry>
        <cylinder length="0.25" radius="0.3"/>
      </geometry>
    </collision>
  </link>
  <joint name="front_right_wheel_joint" type="continuous">
    <parent link="right_diff_unit_link"/>
    <child link="front_right_wheel_link"/>
    <origin rpy="0 0 0" xyz="0.457367 -0.0 -0.012977"/>
    <axis xyz="0 1 0"/>
  </joint>
  <gazebo reference="front_right_wheel_link">
    <selfCollide>false</selfCollide>
    <mu1>0.5</mu1>
    <mu2>0.5</mu2>
    <kp value="10000000.0"/>
    <kd value="1.0"/>
    <fdir1 value="1 0 0"/>
    <material>Gazebo/Grey</material>
  </gazebo>
  <transmission name="front_right_wheel_trans">
    <type>transmission_interface/SimpleTransmission</type>
    <joint name="front_right_wheel_joint">
      <hardwareInterface>hardware_interface/VelocityJointInterface</hardwareInterface>
    </joint>
    <actuator name="front_right_actuator">
      <hardwareInterface>hardware_interface/VelocityJointInterface</hardwareInterface>
      <mechanicalReduction>1</mechanicalReduction>
    </actuator>
  </transmission>
  <link name="rear_left_wheel_link">
    <inertial>
      <origin rpy="0 0 0" xyz="0 0 0"/>
      <mass value="15"/>
      <inertia ixx="0.415625" ixy="0" ixz="0" iyy="0.675" iyz="0" izz="0.415625"/>
    </inertial>
    <visual>
      <origin rpy="0 0 1.57079632679" xyz="0 0 0"/>
      <geometry>
        <mesh filename="package://platform_description/meshes/wheel.stl"/>
      </geometry>
      <material name="dark_grey"/>
    </visual>
    <collision>
      <origin rpy="1.57079632679 0 0" xyz="0 0 0"/>
      <geometry>
        <cylinder length="0.25" radius="0.3"/>
      </geometry>
    </collision>
  </link>
  <joint name="rear_left_wheel_joint" type="continuous">
    <parent link="left_diff_unit_link"/>
    <child link="rear_left_wheel_link"/>
    <origin rpy="0 0 0" xyz="-0.457367 0.0 -0.012977"/>
    <axis xyz="0 1 0"/>
  </joint>
  <gazebo reference="rear_left_wheel_link">
    <selfCollide>false</selfCollide>
    <mu1>0.5</mu1>
    <mu2>0.5</mu2>
    <kp value="10000000.0"/>
    <kd value="1.0"/>
    <fdir1 value="1 0 0"/>
    <material>Gazebo/Grey</material>
  </gazebo>
  <transmission name="rear_left_wheel_trans">
    <type>transmission_interface/SimpleTransmission</type>
    <joint name="rear_left_wheel_joint">
      <hardwareInterface>hardware_interface/VelocityJointInterface</hardwareInterface>
    </joint>
    <actuator name="rear_left_actuator">
      <hardwareInterface>hardware_interface/VelocityJointInterface</hardwareInterface>
      <mechanicalReduction>1</mechanicalReduction>
    </actuator>
  </transmission>
  <link name="rear_right_wheel_link">
    <inertial>
      <origin rpy="0 0 0" xyz="0 0 0"/>
      <mass value="15"/>
      <inertia ixx="0.415625" ixy="0" ixz="0" iyy="0.675" iyz="0" izz="0.415625"/>
    </inertial>
    <visual>
      <origin rpy="0 0 1.57079632679" xyz="0 0 0"/>
      <geometry>
        <mesh filename="package://platform_description/meshes/wheel.stl"/>
      </geometry>
      <material name="dark_grey"/>
    </visual>
    <collision>
      <origin rpy="1.57079632679 0 0" xyz="0 0 0"/>
      <geometry>
        <cylinder length="0.25" radius="0.3"/>
      </geometry>
    </collision>
  </link>
  <joint name="rear_right_wheel_joint" type="continuous">
    <parent link="right_diff_unit_link"/>
    <child link="rear_right_wheel_link"/>
    <origin rpy="0 0 0" xyz="-0.457367 -0.0 -0.012977"/>
    <axis xyz="0 1 0"/>
  </joint>
  <gazebo reference="rear_right_wheel_link">
    <selfCollide>false</selfCollide>
    <mu1>0.5</mu1>
    <mu2>0.5</mu2>
    <kp value="10000000.0"/>
    <kd value="1.0"/>
    <fdir1 value="1 0 0"/>
    <material>Gazebo/Grey</material>
  </gazebo>
  <transmission name="rear_right_wheel_trans">
    <type>transmission_interface/SimpleTransmission</type>
    <joint name="rear_right_wheel_joint">
      <hardwareInterface>hardware_interface/VelocityJointInterface</hardwareInterface>
    </joint>
    <actuator name="rear_right_actuator">
      <hardwareInterface>hardware_interface/VelocityJointInterface</hardwareInterface>
      <mechanicalReduction>1</mechanicalReduction>
    </actuator>
  </transmission>
  <link name="left_diff_unit_link">
    <inertial>
      <origin rpy="0 0 0" xyz="0 -0.05 0.197"/>
      <mass value="50"/>
      <inertia ixx="1.98041666667" ixy="0" ixz="0" iyy="9.13541666667" iyz="0" izz="9.13541666667"/>
    </inertial>
    <visual>
      <origin rpy="0 0 1.57079632679" xyz="0 0 0"/>
      <geometry>
        <mesh filename="package://platform_description/meshes/rocker.stl"/>
      </geometry>
      <material name="black">
        <color rgba="0.15 0.15 0.15 1.0"/>
      </material>
    </visual>
    <visual>
      <origin rpy="0 0 1.57079632679" xyz="0 0 0"/>
      <geometry>
        <mesh filename="package://platform_description/meshes/fenders.stl"/>
      </geometry>
      <material name="yellow">
        <color rgba="0.95 0.816 0.082 1.0"/>
      </material>
    </visual>
    <visual>
      <origin rpy="0 0 0" xyz="0 -0.0244 0"/>
      <geometry>
        <mesh filename="package://platform_description/meshes/light.stl"/>
      </geometry>
      <material name="white">
        <color rgba="0.9 0.9 0.9 1.0"/>
      </material>
    </visual>
    <visual>
      <origin rpy="0 0 3.14159265359" xyz="0 -0.0244 0"/>
      <geometry>
        <mesh filename="package://platform_description/meshes/light.stl"/>
      </geometry>
      <material name="red">
        <color rgba="0.9 0.0 0.0 1.0"/>
      </material>
    </visual>
    <collision>
      <origin rpy="0 0 1.57079632679" xyz="0 0 0"/>
      <geometry>
        <mesh filename="package://platform_description/meshes/fenders.stl"/>
      </geometry>
    </collision>
  </link>
  <joint name="left_diff_unit_joint" type="revolute">
    <limit effort="100" lower="-0.4" upper="0.4" velocity="1"/>
    <parent link="chassis_link"/>
    <child link="left_diff_unit_link"/>
    <origin rpy="0 0 0" xyz="0.0 0.56821 0.0"/>
    <axis xyz="0 1 0"/>
    <dynamics damping="100" friction="0.5"/>
  </joint>
  <gazebo reference="left_diff_unit_link">
    <selfCollide>false</selfCollide>
    <material>Gazebo/Yellow</material>
  </gazebo>
  <link name="right_diff_unit_link">
    <inertial>
      <origin rpy="0 0 0" xyz="0 0.05 0.197"/>
      <mass value="50"/>
      <inertia ixx="1.98041666667" ixy="0" ixz="0" iyy="9.13541666667" iyz="0" izz="9.13541666667"/>
    </inertial>
    <visual>
      <origin rpy="0 0 -1.57079632679" xyz="0 0 0"/>
      <geometry>
        <mesh filename="package://platform_description/meshes/rocker.stl"/>
      </geometry>
      <material name="black">
        <color rgba="0.15 0.15 0.15 1.0"/>
      </material>
    </visual>
    <visual>
      <origin rpy="0 0 -1.57079632679" xyz="0 0 0"/>
      <geometry>
        <mesh filename="package://platform_description/meshes/fenders.stl"/>
      </geometry>
      <material name="yellow">
        <color rgba="0.95 0.816 0.082 1.0"/>
      </material>
    </visual>
    <visual>
      <origin rpy="0 0 0" xyz="0 0.0244 0"/>
      <geometry>
        <mesh filename="package://platform_description/meshes/light.stl"/>
      </geometry>
      <material name="white">
        <color rgba="0.9 0.9 0.9 1.0"/>
      </material>
    </visual>
    <visual>
      <origin rpy="0 0 -3.14159265359" xyz="0 0.0244 0"/>
      <geometry>
        <mesh filename="package://platform_description/meshes/light.stl"/>
      </geometry>
      <material name="red">
        <color rgba="0.9 0.0 0.0 1.0"/>
      </material>
    </visual>
    <collision>
      <origin rpy="0 0 -1.57079632679" xyz="0 0 0"/>
      <geometry>
        <mesh filename="package://platform_description/meshes/fenders.stl"/>
      </geometry>
    </collision>
  </link>
  <joint name="right_diff_unit_joint" type="revolute">
    <limit effort="100" lower="-0.4" upper="0.4" velocity="1"/>
    <parent link="chassis_link"/>
    <child link="right_diff_unit_link"/>
    <origin rpy="0 0 0" xyz="0.0 -0.56821 0.0"/>
    <axis xyz="0 1 0"/>
    <dynamics damping="100" friction="0.5"/>
  </joint>
  <gazebo reference="right_diff_unit_link">
    <selfCollide>false</selfCollide>
    <material>Gazebo/Yellow</material>
  </gazebo>
  <link name="base_link"/>
  <joint name="base_link_joint" type="fixed">
    <origin rpy="0 0 0" xyz="0 0 0.025"/>
    <parent link="base_link"/>
    <child link="chassis_link"/>
  </joint>
  <link name="chassis_link">
    <inertial>
      <origin rpy="0 0 0" xyz="0 0 0"/>
      <mass value="100"/>
      <inertia ixx="4.83333333333" ixy="0" ixz="0" iyy="15.9375" iyz="0" izz="15.9375"/>
    </inertial>
    <visual>
      <origin rpy="0 0 0" xyz="0 0 0"/>
      <geometry>
        <mesh filename="package://platform_description/meshes/chassis.stl"/>
      </geometry>
      <material name="black">
        <color rgba="0.15 0.15 0.15 1.0"/>
      </material>
    </visual>
    <visual>
      <origin rpy="0 0 0" xyz="0 0 0"/>
      <geometry>
        <mesh filename="package://platform_description/meshes/e-stop.stl"/>
      </geometry>
      <material name="red">
        <color rgba="0.9 0.0 0.0 1.0"/>
      </material>
    </visual>
    <collision>
      <origin rpy="0 0 0" xyz="0 0 0"/>
      <geometry>
        <mesh filename="package://platform_description/meshes/chassis-collision.stl"/>
      </geometry>
    </collision>
  </link>
  <link name="top_chassis_link"/>
  <joint name="top_link_joint" type="fixed">
    <origin rpy="0 0 0" xyz="0 0 0.27218"/>
    <parent link="chassis_link"/>
    <child link="top_chassis_link"/>
  </joint>
  <!-- This link is purely to complete the visual look -->
  <link name="diff_link">
    <visual>
      <origin rpy="0 0 0" xyz="0 0 0"/>
      <geometry>
        <mesh filename="package://platform_description/meshes/diff-link.stl"/>
      </geometry>
      <material name="light_grey"/>
    </visual>
    <visual>
      <origin rpy="0 0 0" xyz="0 0 0"/>
      <geometry>
        <mesh filename="package://platform_description/meshes/susp-link.stl"/>
      </geometry>
      <material name="light_grey"/>
    </visual>
    <visual>
      <origin rpy="0 0 0" xyz="0 0 0"/>
      <geometry>
        <mesh filename="package://platform_description/meshes/susp-link.stl"/>
      </geometry>
      <material name="light_grey"/>
    </visual>
  </link>
  <joint name="diff_link_joint" type="fixed">
    <parent link="chassis_link"/>
    <child link="diff_link"/>
    <origin rpy="0 0 0" xyz="-0.5826 0 0.24979"/>
  </joint>
  <!-- Sensor Frame. -->
  <link name="imu_link"/>
  <joint name="imu_link_joint" type="fixed">
    <parent link="top_chassis_link"/>
    <child link="imu_link"/>
    <origin rpy="0 3.1415926 -3.1415926" xyz="-0.26 0 0.445"/>
  </joint>
  <link name="velodyne"/>
  <joint name="imu_to_velodyne" type="fixed">
    <parent link="imu_link"/>
    <child link="velodyne"/>
    <origin rpy="0 3.1415926 -3.1415926" xyz="0.6 0 0"/>
  </joint>
  <link name="os1_frame"/>
  <joint name="os1_to_imu" type="fixed">
    <parent link="imu_link"/>
    <child link="os1_frame"/>
    <origin rpy="0 3.1415926 0" xyz="0.45 0 -0.07"/>
  </joint>
  <link name="ouster1/os1_sensor"/>
  <joint name="os1_sensor_to_os1_frame" type="fixed">
    <parent link="os1_frame"/>
    <child link="ouster1/os1_sensor"/>
    <origin rpy="0 0 -3.1415926" xyz="0 0 0"/>
  </joint>
  <link name="ouster1/os1_lidar"/>
  <joint name="os1_lidar_to_os1_sensor" type="fixed">
    <parent link="ouster1/os1_sensor"/>
    <child link="ouster1/os1_lidar"/>
    <origin rpy="0 0 -3.1415927" xyz="0 0 0.03618"/>
  </joint>
  <link name="ouster1/os1_imu"/>
  <joint name="os1_imu_to_os1_sensor" type="fixed">
    <parent link="ouster1/os1_sensor"/>
    <child link="ouster1/os1_imu"/>
    <origin rpy="0 0 0" xyz="0.006253 -0.011775 0.007645"/>
  </joint>
  <!-- Bring in simulation data for Gazebo. -->
  <!--xacro:include filename="$(find platform_description)/urdf/warthog.gazebo" /-->
  <!-- Optional standard accessories, including their simulation data. The rendering
       of these into the final description is controlled by optenv variables, which
       default each one to off.-->
  <!--xacro:include filename="$(find platform_description)/urdf/accessories.urdf.xacro" /-->
  <!-- Optional custom includes. -->
  <!--xacro:include filename="$(optenv WARTHOG_URDF_EXTRAS empty.urdf)" /-->
</robot>
